<?xml version="1.0" encoding="utf-8"?>

<robot name="mrobot_chassis"> 
  <!-- 底盘 -->  
  <link name="base_link">
    <!-- 物理惯性属性 -->
    <inertial>
      <mass value="2" />
      <origin xyz="0 0 0.0" />
      <inertia ixx="0.01" ixy="0.0" ixz="0.0" iyy="0.01" iyz="0.0" izz="0.5" />
    </inertial>
    <!-- 外观 -->
    <visual> 
      <!-- 空间位置和姿态 rpy的单位: 弧度 -->
      <origin>xyz="0 0 0" rpy="0 0 0"</origin>  
      <geometry> 
        <!-- 圆柱 长度单位：m -->
        <cylinder length="0.005" radius="0.13"/> 
      </geometry>  
      <material name="yellow"> 
        <color rgba="1 0.4 0 1"/> 
      </material> 
    </visual> 
    <!-- 碰撞属性 -->
    <collision>
      <origin xyz="0 0 0" rpy="0 0 0" />
      <geometry>
        <cylinder length="0.005" radius="0.13"/>
      </geometry>
    </collision>
  </link>    
  <joint name="base_left_motor_joint" type="fixed">
    <!--关节的起点-->
    <origin xyz="-0.055 0.075 0" rpy="0 0 0"/>  
    <parent link="base_link"/>  
    <child link="left_motor"/> 
  </joint>  
  <!-- 左轮电机 -->
  <link name="left_motor"> 
    <visual> 
      <origin xyz="0 0 0" rpy="1.5707 0 0"/>  
      <geometry>
        <cylinder radius="0.02" length="0.08"/> 
      </geometry>  
      <material name="gray"> 
        <color rgba="0.75 0.75 0.75 1"/> 
      </material> 
    </visual> 
  </link>  
  <!-- 左轮轴 -->
  <joint name="left_wheel_joint" type="continuous"> 
    <origin xyz="0 0.0485 0" rpy="0 0 0"/>  
    <parent link="left_motor"/>  
    <child link="left_wheel_link"/>  
    <!-- 旋转轴 -->
    <axis xyz="0 1 0"/> 
  </joint>
  <!-- 左轮 -->
  <link name="left_wheel_link"> 
    <visual> 
      <origin xyz="0 0 0" rpy="1.5707 0 0"/>  
      <geometry> 
        <cylinder radius="0.033" length="0.017"/> 
      </geometry>  
      <material name="white"> 
        <color rgba="1 1 1 0.9"/> 
      </material>
    </visual> 
  </link>  
  <!-- 右轮 -->  
  <joint name="base_right_motor_joint" type="fixed"> 
    <origin xyz="-0.055 -0.075 0" rpy="0 0 0"/>  
    <parent link="base_link"/>  
    <child link="right_motor"/> 
  </joint>  
  <link name="right_motor"> 
    <visual> 
      <origin xyz="0 0 0" rpy="1.5707 0 0"/>  
      <geometry> 
        <cylinder radius="0.02" length="0.08"/> 
      </geometry>  
      <material name="gray"> 
        <color rgba="0.75 0.75 0.75 1"/> 
      </material> 
    </visual> 
  </link>  
  <joint name="right_wheel_joint" type="continuous"> 
    <origin xyz="0 -0.0485 0" rpy="0 0 0"/>  
    <parent link="right_motor"/>  
    <child link="right_wheel_link"/>  
    <axis xyz="0 1 0"/> 
  </joint>  
  <link name="right_wheel_link"> 
    <visual> 
      <origin xyz="0 0 0" rpy="1.5707 0 0"/>  
      <geometry> 
        <cylinder radius="0.033" length="0.017"/> 
      </geometry>  
      <material name="white"> 
        <color rgba="1 1 1 0.9"/> 
      </material> 
    </visual> 
  </link>  
  <!--  -->  
  <joint name="front_castor_joint" type="fixed"> 
    <origin xyz="0.1135 0 -0.0165" rpy="0 0 0"/>  
    <parent link="base_link"/>  
    <child link="front_castor_link"/>  
    <axis xyz="0 1 0"/> 
  </joint>  
  <link name="front_castor_link"> 
    <visual> 
      <origin xyz="0 0 0" rpy="1.5707 0 0"/>  
      <geometry> 
        <sphere radius="0.0165"/> 
      </geometry>  
      <material name="black"> 
        <color rgba="0 0 0 0.95"/> 
      </material> 
    </visual> 
  </link> 
</robot>
